Workbook

Sheet Summary
A1: City | B1: Sales Performance 2026 | G1: Total Sales by City
B2: Accessories | C2: Electronics | D2: Books | E2: Fashion | F2: Home Appliances
A3: Hyderabad | B3: =SUMIFS(ecommerce_sales_1000_records!$E:E,ecommerce_sales_1000_records!$C:C,Summary!B$2,ecommerce_sales_1000_records!$F:F,Summary!$A3) -> 48195.42 | C3: =SUMIFS(ecommerce_sales_1000_records!$E:F,ecommerce_sales_1000_records!$C:D,Summary!C$2,ecommerce_sales_1000_records!$F:G,Summary!$A3) -> 475523.37 | D3: =SUMIFS(ecommerce_sales_1000_records!$E:G,ecommerce_sales_1000_records!$C:E,Summary!D$2,ecommerce_sales_1000_records!$F:H,Summary!$A3) -> 3082.09 | E3: =SUMIFS(ecommerce_sales_1000_records!$E:H,ecommerce_sales_1000_records!$C:F,Summary!E$2,ecommerce_sales_1000_records!$F:I,Summary!$A3) -> 51629.74 | F3: =SUMIFS(ecommerce_sales_1000_records!$E:I,ecommerce_sales_1000_records!$C:G,Summary!F$2,ecommerce_sales_1000_records!$F:J,Summary!$A3) -> 84550.9 | G3: =SUM(B3:F3) -> 662981.52
A4: Surat | B4: =SUMIFS(ecommerce_sales_1000_records!$E:E,ecommerce_sales_1000_records!$C:C,Summary!B$2,ecommerce_sales_1000_records!$F:F,Summary!$A4) -> 50598.48 | C4: =SUMIFS(ecommerce_sales_1000_records!$E:F,ecommerce_sales_1000_records!$C:D,Summary!C$2,ecommerce_sales_1000_records!$F:G,Summary!$A4) -> 642996.84 | D4: =SUMIFS(ecommerce_sales_1000_records!$E:G,ecommerce_sales_1000_records!$C:E,Summary!D$2,ecommerce_sales_1000_records!$F:H,Summary!$A4) -> 2258.4 | E4: =SUMIFS(ecommerce_sales_1000_records!$E:H,ecommerce_sales_1000_records!$C:F,Summary!E$2,ecommerce_sales_1000_records!$F:I,Summary!$A4) -> 46839.38 | F4: =SUMIFS(ecommerce_sales_1000_records!$E:I,ecommerce_sales_1000_records!$C:G,Summary!F$2,ecommerce_sales_1000_records!$F:J,Summary!$A4) -> 85271.29 | G4: =SUM(B4:F4) -> 827964.39
A5: Mumbai | B5: =SUMIFS(ecommerce_sales_1000_records!$E:E,ecommerce_sales_1000_records!$C:C,Summary!B$2,ecommerce_sales_1000_records!$F:F,Summary!$A5) -> 50626.4 | C5: =SUMIFS(ecommerce_sales_1000_records!$E:F,ecommerce_sales_1000_records!$C:D,Summary!C$2,ecommerce_sales_1000_records!$F:G,Summary!$A5) -> 781774.04 | D5: =SUMIFS(ecommerce_sales_1000_records!$E:G,ecommerce_sales_1000_records!$C:E,Summary!D$2,ecommerce_sales_1000_records!$F:H,Summary!$A5) -> 4106.52 | E5: =SUMIFS(ecommerce_sales_1000_records!$E:H,ecommerce_sales_1000_records!$C:F,Summary!E$2,ecommerce_sales_1000_records!$F:I,Summary!$A5) -> 56419.27 | F5: =SUMIFS(ecommerce_sales_1000_records!$E:I,ecommerce_sales_1000_records!$C:G,Summary!F$2,ecommerce_sales_1000_records!$F:J,Summary!$A5) -> 117422.07 | G5: =SUM(B5:F5) -> 1010348.3
A6: Jaipur | B6: =SUMIFS(ecommerce_sales_1000_records!$E:E,ecommerce_sales_1000_records!$C:C,Summary!B$2,ecommerce_sales_1000_records!$F:F,Summary!$A6) -> 67401.04 | C6: =SUMIFS(ecommerce_sales_1000_records!$E:F,ecommerce_sales_1000_records!$C:D,Summary!C$2,ecommerce_sales_1000_records!$F:G,Summary!$A6) -> 950342.85 | D6: =SUMIFS(ecommerce_sales_1000_records!$E:G,ecommerce_sales_1000_records!$C:E,Summary!D$2,ecommerce_sales_1000_records!$F:H,Summary!$A6) -> 4163.08 | E6: =SUMIFS(ecommerce_sales_1000_records!$E:H,ecommerce_sales_1000_records!$C:F,Summary!E$2,ecommerce_sales_1000_records!$F:I,Summary!$A6) -> 29865.08 | F6: =SUMIFS(ecommerce_sales_1000_records!$E:I,ecommerce_sales_1000_records!$C:G,Summary!F$2,ecommerce_sales_1000_records!$F:J,Summary!$A6) -> 96860.33 | G6: =SUM(B6:F6) -> 1148632.4
A7: Delhi | B7: =SUMIFS(ecommerce_sales_1000_records!$E:E,ecommerce_sales_1000_records!$C:C,Summary!B$2,ecommerce_sales_1000_records!$F:F,Summary!$A7) -> 30365.77 | C7: =SUMIFS(ecommerce_sales_1000_records!$E:F,ecommerce_sales_1000_records!$C:D,Summary!C$2,ecommerce_sales_1000_records!$F:G,Summary!$A7) -> 725393.79 | D7: =SUMIFS(ecommerce_sales_1000_records!$E:G,ecommerce_sales_1000_records!$C:E,Summary!D$2,ecommerce_sales_1000_records!$F:H,Summary!$A7) -> 3116 | E7: =SUMIFS(ecommerce_sales_1000_records!$E:H,ecommerce_sales_1000_records!$C:F,Summary!E$2,ecommerce_sales_1000_records!$F:I,Summary!$A7) -> 42192.05 | F7: =SUMIFS(ecommerce_sales_1000_records!$E:I,ecommerce_sales_1000_records!$C:G,Summary!F$2,ecommerce_sales_1000_records!$F:J,Summary!$A7) -> 123675.32 | G7: =SUM(B7:F7) -> 924742.93
A8: Bangalore | B8: =SUMIFS(ecommerce_sales_1000_records!$E:E,ecommerce_sales_1000_records!$C:C,Summary!B$2,ecommerce_sales_1000_records!$F:F,Summary!$A8) -> 80895.79 | C8: =SUMIFS(ecommerce_sales_1000_records!$E:F,ecommerce_sales_1000_records!$C:D,Summary!C$2,ecommerce_sales_1000_records!$F:G,Summary!$A8) -> 697673.74 | D8: =SUMIFS(ecommerce_sales_1000_records!$E:G,ecommerce_sales_1000_records!$C:E,Summary!D$2,ecommerce_sales_1000_records!$F:H,Summary!$A8) -> 1385.6 | E8: =SUMIFS(ecommerce_sales_1000_records!$E:H,ecommerce_sales_1000_records!$C:F,Summary!E$2,ecommerce_sales_1000_records!$F:I,Summary!$A8) -> 18620.86 | F8: =SUMIFS(ecommerce_sales_1000_records!$E:I,ecommerce_sales_1000_records!$C:G,Summary!F$2,ecommerce_sales_1000_records!$F:J,Summary!$A8) -> 137809.13 | G8: =SUM(B8:F8) -> 936385.12
A9: Pune | B9: =SUMIFS(ecommerce_sales_1000_records!$E:E,ecommerce_sales_1000_records!$C:C,Summary!B$2,ecommerce_sales_1000_records!$F:F,Summary!$A9) -> 58984.12 | C9: =SUMIFS(ecommerce_sales_1000_records!$E:F,ecommerce_sales_1000_records!$C:D,Summary!C$2,ecommerce_sales_1000_records!$F:G,Summary!$A9) -> 870104.23 | D9: =SUMIFS(ecommerce_sales_1000_records!$E:G,ecommerce_sales_1000_records!$C:E,Summary!D$2,ecommerce_sales_1000_records!$F:H,Summary!$A9) -> 2742.72 | E9: =SUMIFS(ecommerce_sales_1000_records!$E:H,ecommerce_sales_1000_records!$C:F,Summary!E$2,ecommerce_sales_1000_records!$F:I,Summary!$A9) -> 38005.1 | F9: =SUMIFS(ecommerce_sales_1000_records!$E:I,ecommerce_sales_1000_records!$C:G,Summary!F$2,ecommerce_sales_1000_records!$F:J,Summary!$A9) -> 111480.52 | G9: =SUM(B9:F9) -> 1081316.7
A10: Ahmedabad | B10: =SUMIFS(ecommerce_sales_1000_records!$E:E,ecommerce_sales_1000_records!$C:C,Summary!B$2,ecommerce_sales_1000_records!$F:F,Summary!$A10) -> 86208.89 | C10: =SUMIFS(ecommerce_sales_1000_records!$E:F,ecommerce_sales_1000_records!$C:D,Summary!C$2,ecommerce_sales_1000_records!$F:G,Summary!$A10) -> 506061.74 | D10: =SUMIFS(ecommerce_sales_1000_records!$E:G,ecommerce_sales_1000_records!$C:E,Summary!D$2,ecommerce_sales_1000_records!$F:H,Summary!$A10) -> 3248.53 | E10: =SUMIFS(ecommerce_sales_1000_records!$E:H,ecommerce_sales_1000_records!$C:F,Summary!E$2,ecommerce_sales_1000_records!$F:I,Summary!$A10) -> 33186.92 | F10: =SUMIFS(ecommerce_sales_1000_records!$E:I,ecommerce_sales_1000_records!$C:G,Summary!F$2,ecommerce_sales_1000_records!$F:J,Summary!$A10) -> 96169.9 | G10: =SUM(B10:F10) -> 724875.98
A11: Chennai | B11: =SUMIFS(ecommerce_sales_1000_records!$E:E,ecommerce_sales_1000_records!$C:C,Summary!B$2,ecommerce_sales_1000_records!$F:F,Summary!$A11) -> 43817.18 | C11: =SUMIFS(ecommerce_sales_1000_records!$E:F,ecommerce_sales_1000_records!$C:D,Summary!C$2,ecommerce_sales_1000_records!$F:G,Summary!$A11) -> 577807.15 | D11: =SUMIFS(ecommerce_sales_1000_records!$E:G,ecommerce_sales_1000_records!$C:E,Summary!D$2,ecommerce_sales_1000_records!$F:H,Summary!$A11) -> 3112.52 | E11: =SUMIFS(ecommerce_sales_1000_records!$E:H,ecommerce_sales_1000_records!$C:F,Summary!E$2,ecommerce_sales_1000_records!$F:I,Summary!$A11) -> 36310.28 | F11: =SUMIFS(ecommerce_sales_1000_records!$E:I,ecommerce_sales_1000_records!$C:G,Summary!F$2,ecommerce_sales_1000_records!$F:J,Summary!$A11) -> 87468.52 | G11: =SUM(B11:F11) -> 748515.65
A12: Kolkata | B12: =SUMIFS(ecommerce_sales_1000_records!$E:E,ecommerce_sales_1000_records!$C:C,Summary!B$2,ecommerce_sales_1000_records!$F:F,Summary!$A12) -> 23959.38 | C12: =SUMIFS(ecommerce_sales_1000_records!$E:F,ecommerce_sales_1000_records!$C:D,Summary!C$2,ecommerce_sales_1000_records!$F:G,Summary!$A12) -> 708732.02 | D12: =SUMIFS(ecommerce_sales_1000_records!$E:G,ecommerce_sales_1000_records!$C:E,Summary!D$2,ecommerce_sales_1000_records!$F:H,Summary!$A12) -> 2673.58 | E12: =SUMIFS(ecommerce_sales_1000_records!$E:H,ecommerce_sales_1000_records!$C:F,Summary!E$2,ecommerce_sales_1000_records!$F:I,Summary!$A12) -> 35582.71 | F12: =SUMIFS(ecommerce_sales_1000_records!$E:I,ecommerce_sales_1000_records!$C:G,Summary!F$2,ecommerce_sales_1000_records!$F:J,Summary!$A12) -> 103775.56 | G12: =SUM(B12:F12) -> 874723.25
A15: Category | B15: Actual sales | H15: Forecated Sales | N15: Sales 2026
B16: 46023 | C16: 46054 | D16: 46082 | E16: 46113 | F16: 46143 | G16: 46174 | H16: 46204 | I16: 46235 | J16: 46266 | K16: 46296 | L16: 46327 | M16: 46357
A17: Accessories | B17: 67358.35 | C17: 99356.48 | D17: 100539.58 | E17: 86704.88 | F17: 76709.79 | G17: 110383.39 | H17: =AVERAGE(E17:G17)*105% -> 95829.321 | I17: =AVERAGE(F17:H17)*105% -> 99022.875 | J17: =AVERAGE(G17:I17)*105% -> 106832.46 | K17: =AVERAGE(H17:J17)*105% -> 105589.63 | L17: =AVERAGE(I17:K17)*105% -> 109005.74 | M17: =AVERAGE(J17:L17)*105% -> 112499.74 | N17: =SUM(B17:M17) -> 1169832.2
A18: Electronics | B18: 1518548 | C18: 1044268.1 | D18: 1111658.2 | E18: 1222701.8 | F18: 1304164.5 | G18: 735069.27 | H18: =AVERAGE(E18:G18)*105% -> 1141677.4 | I18: =AVERAGE(F18:H18)*105% -> 1113318.9 | J18: =AVERAGE(G18:I18)*105% -> 1046523 | K18: =AVERAGE(H18:J18)*105% -> 1155531.8 | L18: =AVERAGE(I18:K18)*105% -> 1160380.8 | M18: =AVERAGE(J18:L18)*105% -> 1176852.4 | N18: =SUM(B18:M18) -> 13730694
A19: Books | B19: 6033.74 | C19: 4974.32 | D19: 5430.06 | E19: 2213.98 | F19: 4565.48 | G19: 6671.46 | H19: =AVERAGE(E19:G19)*105% -> 4707.822 | I19: =AVERAGE(F19:H19)*105% -> 5580.6667 | J19: =AVERAGE(G19:I19)*105% -> 5935.982 | K19: =AVERAGE(H19:J19)*105% -> 5678.5648 | L19: =AVERAGE(I19:K19)*105% -> 6018.3247 | M19: =AVERAGE(J19:L19)*105% -> 6171.505 | N19: =SUM(B19:M19) -> 63981.905
A20: Fashion | B20: 65031.48 | C20: 57796.06 | D20: 59196.43 | E20: 71362.62 | F20: 80989.91 | G20: 54274.89 | H20: =AVERAGE(E20:G20)*105% -> 72319.597 | I20: =AVERAGE(F20:H20)*105% -> 72654.539 | J20: =AVERAGE(G20:I20)*105% -> 69737.159 | K20: =AVERAGE(H20:J20)*105% -> 75148.953 | L20: =AVERAGE(I20:K20)*105% -> 76139.228 | M20: =AVERAGE(J20:L20)*105% -> 77358.869 | N20: =SUM(B20:M20) -> 832009.74
A21: Home Appliances | B21: 154798.52 | C21: 126137.84 | D21: 213421.06 | E21: 178787.71 | F21: 225640.29 | G21: 145698.12 | H21: =AVERAGE(E21:G21)*105% -> 192544.14 | I21: =AVERAGE(F21:H21)*105% -> 197358.89 | J21: =AVERAGE(G21:I21)*105% -> 187460.4 | K21: =AVERAGE(H21:J21)*105% -> 202077.2 | L21: =AVERAGE(I21:K21)*105% -> 205413.78 | M21: =AVERAGE(J21:L21)*105% -> 208232.98 | N21: =SUM(B21:M21) -> 2237570.9
A22: Total Sales by Month: | B22: =SUM(B17:B21) -> 1811770.1 | C22: =SUM(C17:C21) -> 1332532.8 | D22: =SUM(D17:D21) -> 1490245.3 | E22: =SUM(E17:E21) -> 1561770.9 | F22: =SUM(F17:F21) -> 1692070 | G22: =SUM(G17:G21) -> 1052097.1 | H22: =SUM(H17:H21) -> 1507078.3 | I22: =SUM(I17:I21) -> 1487935.9 | ... M22: =SUM(M17:M21) -> 1581115.5 | N22: =SUM(B22:M22) -> 18034089
A24: Trend | B24: 2 month | C24: 3 month | D24: 4 month | E24: 5 month | F24: 6 month | G24: Average
A25: Accessories | B25: =(C17-B17)/B17 -> 0.47504326 | C25: =(D17-C17)/C17 -> 0.011907628 | D25: =(E17-D17)/D17 -> -0.13760451 | E25: =(F17-E17)/E17 -> -0.11527713 | F25: =(G17-F17)/F17 -> 0.43897396 | G25: =AVERAGE(B25:F25) -> 0.13460864
A26: Electronics | B26: =(C18-B18)/B18 -> -0.31232461 | C26: =(D18-C18)/C18 -> 0.064533305 | D26: =(E18-D18)/D18 -> 0.099890061 | E26: =(F18-E18)/E18 -> 0.066625226 | F26: =(G18-F18)/F18 -> -0.43636769 | G26: =AVERAGE(B26:F26) -> -0.10352874
A27: Books | B27: =(C19-B19)/B19 -> -0.17558264 | C27: =(D19-C19)/C19 -> 0.091618553 | D27: =(E19-D19)/D19 -> -0.59227338 | E27: =(F19-E19)/E19 -> 1.0621144 | F27: =(G19-F19)/F19 -> 0.46128337 | G27: =AVERAGE(B27:F27) -> 0.16943206
A28: Fashion | B28: =(C20-B20)/B20 -> -0.11126027 | C28: =(D20-C20)/C20 -> 0.024229506 | D28: =(E20-D20)/D20 -> 0.20552236 | E28: =(F20-E20)/E20 -> 0.13490662 | F28: =(G20-F20)/F20 -> -0.32985615 | G28: =AVERAGE(B28:F28) -> -0.015291587
A29: Home Appliances | B29: =(C21-B21)/B21 -> -0.18514828 | C29: =(D21-C21)/C21 -> 0.69196698 | D29: =(E21-D21)/D21 -> -0.1622771 | E29: =(F21-E21)/E21 -> 0.26205705 | F29: =(G21-F21)/F21 -> -0.35429032 | G29: =AVERAGE(B29:F29) -> 0.050461667
A30: Average | B30: =AVERAGE(B25:B29) -> -0.061854509 | C30: =AVERAGE(C25:C29) -> 0.17685119 | D30: =AVERAGE(D25:D29) -> -0.11734851 | E30: =AVERAGE(E25:E29) -> 0.28208523 | F30: =AVERAGE(F25:F29) -> -0.044051366 | G30: =AVERAGE(G25:G29) -> 0.047136407

Sheet MTD
A1: Date | B1: 46023 | C1: 46023 | D1: =C1+1 -> 46024 | E1: =D1+1 -> 46025 | F1: =E1+1 -> 46026 | G1: =F1+1 -> 46027 | H1: =G1+1 -> 46028 | I1: =H1+1 -> 46029 | J1: =I1+1 -> 46030 | K1: =J1+1 -> 46031 | ... AG1: =AF1+1 -> 46053
A2: Accessories | B2: =SUM(C2:AG2) -> 67358.35 | C2: =SUMIFS(ecommerce_sales_1000_records!$E:E,ecommerce_sales_1000_records!$G:G,MTD!C$1,ecommerce_sales_1000_records!$C:C,MTD!$A2) -> 1702.23 | D2: =SUMIFS(ecommerce_sales_1000_records!$E:F,ecommerce_sales_1000_records!$G:H,MTD!D$1,ecommerce_sales_1000_records!$C:D,MTD!$A2) -> 0 | E2: =SUMIFS(ecommerce_sales_1000_records!$E:G,ecommerce_sales_1000_records!$G:I,MTD!E$1,ecommerce_sales_1000_records!$C:E,MTD!$A2) -> 1784.6 | F2: =SUMIFS(ecommerce_sales_1000_records!$E:H,ecommerce_sales_1000_records!$G:J,MTD!F$1,ecommerce_sales_1000_records!$C:F,MTD!$A2) -> 0 | G2: =SUMIFS(ecommerce_sales_1000_records!$E:I,ecommerce_sales_1000_records!$G:K,MTD!G$1,ecommerce_sales_1000_records!$C:G,MTD!$A2) -> 0 | H2: =SUMIFS(ecommerce_sales_1000_records!$E:J,ecommerce_sales_1000_records!$G:L,MTD!H$1,ecommerce_sales_1000_records!$C:H,MTD!$A2) -> 0 | I2: =SUMIFS(ecommerce_sales_1000_records!$E:K,ecommerce_sales_1000_records!$G:M,MTD!I$1,ecommerce_sales_1000_records!$C:I,MTD!$A2) -> 0 | J2: =SUMIFS(ecommerce_sales_1000_records!$E:L,ecommerce_sales_1000_records!$G:N,MTD!J$1,ecommerce_sales_1000_records!$C:J,MTD!$A2) -> 5281.48 | K2: =SUMIFS(ecommerce_sales_1000_records!$E:M,ecommerce_sales_1000_records!$G:O,MTD!K$1,ecommerce_sales_1000_records!$C:K,MTD!$A2) -> 0 | L2: =SUMIFS(ecommerce_sales_1000_records!$E:N,ecommerce_sales_1000_records!$G:P,MTD!L$1,ecommerce_sales_1000_records!$C:L,MTD!$A2) -> 0 | M2: =SUMIFS(ecommerce_sales_1000_records!$E:O,ecommerce_sales_1000_records!$G:Q,MTD!M$1,ecommerce_sales_1000_records!$C:M,MTD!$A2) -> 0 | N2: =SUMIFS(ecommerce_sales_1000_records!$E:P,ecommerce_sales_1000_records!$G:R,MTD!N$1,ecommerce_sales_1000_records!$C:N,MTD!$A2) -> 5354.94 | O2: =SUMIFS(ecommerce_sales_1000_records!$E:Q,ecommerce_sales_1000_records!$G:S,MTD!O$1,ecommerce_sales_1000_records!$C:O,MTD!$A2) -> 1727.06 | P2: =SUMIFS(ecommerce_sales_1000_records!$E:R,ecommerce_sales_1000_records!$G:T,MTD!P$1,ecommerce_sales_1000_records!$C:P,MTD!$A2) -> 3764.08 | Q2: =SUMIFS(ecommerce_sales_1000_records!$E:S,ecommerce_sales_1000_records!$G:U,MTD!Q$1,ecommerce_sales_1000_records!$C:Q,MTD!$A2) -> 4876.19 | R2: =SUMIFS(ecommerce_sales_1000_records!$E:T,ecommerce_sales_1000_records!$G:V,MTD!R$1,ecommerce_sales_1000_records!$C:R,MTD!$A2) -> 0 | S2: =SUMIFS(ecommerce_sales_1000_records!$E:U,ecommerce_sales_1000_records!$G:W,MTD!S$1,ecommerce_sales_1000_records!$C:S,MTD!$A2) -> 0 | T2: =SUMIFS(ecommerce_sales_1000_records!$E:V,ecommerce_sales_1000_records!$G:X,MTD!T$1,ecommerce_sales_1000_records!$C:T,MTD!$A2) -> 7149.93 | U2: =SUMIFS(ecommerce_sales_1000_records!$E:W,ecommerce_sales_1000_records!$G:Y,MTD!U$1,ecommerce_sales_1000_records!$C:U,MTD!$A2) -> 0 | V2: =SUMIFS(ecommerce_sales_1000_records!$E:X,ecommerce_sales_1000_records!$G:Z,MTD!V$1,ecommerce_sales_1000_records!$C:V,MTD!$A2) -> 18443.7 | W2: =SUMIFS(ecommerce_sales_1000_records!$E:Y,ecommerce_sales_1000_records!$G:AA,MTD!W$1,ecommerce_sales_1000_records!$C:W,MTD!$A2) -> 0 | X2: =SUMIFS(ecommerce_sales_1000_records!$E:Z,ecommerce_sales_1000_records!$G:AB,MTD!X$1,ecommerce_sales_1000_records!$C:X,MTD!$A2) -> 0 | Y2: =SUMIFS(ecommerce_sales_1000_records!$E:AA,ecommerce_sales_1000_records!$G:AC,MTD!Y$1,ecommerce_sales_1000_records!$C:Y,MTD!$A2) -> 0 | Z2: =SUMIFS(ecommerce_sales_1000_records!$E:AB,ecommerce_sales_1000_records!$G:AD,MTD!Z$1,ecommerce_sales_1000_records!$C:Z,MTD!$A2) -> 8603.08 | AA2: =SUMIFS(ecommerce_sales_1000_records!$E:AC,ecommerce_sales_1000_records!$G:AE,MTD!AA$1,ecommerce_sales_1000_records!$C:AA,MTD!$A2) -> 1735.31 | AB2: =SUMIFS(ecommerce_sales_1000_records!$E:AD,ecommerce_sales_1000_records!$G:AF,MTD!AB$1,ecommerce_sales_1000_records!$C:AB,MTD!$A2) -> 0 | AC2: =SUMIFS(ecommerce_sales_1000_records!$E:AE,ecommerce_sales_1000_records!$G:AG,MTD!AC$1,ecommerce_sales_1000_records!$C:AC,MTD!$A2) -> 1931.38 | AD2: =SUMIFS(ecommerce_sales_1000_records!$E:AF,ecommerce_sales_1000_records!$G:AH,MTD!AD$1,ecommerce_sales_1000_records!$C:AD,MTD!$A2) -> 1641.82 | AE2: =SUMIFS(ecommerce_sales_1000_records!$E:AG,ecommerce_sales_1000_records!$G:AI,MTD!AE$1,ecommerce_sales_1000_records!$C:AE,MTD!$A2) -> 0 | AF2: =SUMIFS(ecommerce_sales_1000_records!$E:AH,ecommerce_sales_1000_records!$G:AJ,MTD!AF$1,ecommerce_sales_1000_records!$C:AF,MTD!$A2) -> 1739.21 | AG2: =SUMIFS(ecommerce_sales_1000_records!$E:AI,ecommerce_sales_1000_records!$G:AK,MTD!AG$1,ecommerce_sales_1000_records!$C:AG,MTD!$A2) -> 1623.34
A3: Electronics | B3: =SUM(C3:AG3) -> 1518548 | C3: =SUMIFS(ecommerce_sales_1000_records!$E:E,ecommerce_sales_1000_records!$G:G,MTD!C$1,ecommerce_sales_1000_records!$C:C,MTD!$A3) -> 39574.34 | D3: =SUMIFS(ecommerce_sales_1000_records!$E:F,ecommerce_sales_1000_records!$G:H,MTD!D$1,ecommerce_sales_1000_records!$C:D,MTD!$A3) -> 90019.45 | E3: =SUMIFS(ecommerce_sales_1000_records!$E:G,ecommerce_sales_1000_records!$G:I,MTD!E$1,ecommerce_sales_1000_records!$C:E,MTD!$A3) -> 25731.99 | F3: =SUMIFS(ecommerce_sales_1000_records!$E:H,ecommerce_sales_1000_records!$G:J,MTD!F$1,ecommerce_sales_1000_records!$C:F,MTD!$A3) -> 82172.81 | G3: =SUMIFS(ecommerce_sales_1000_records!$E:I,ecommerce_sales_1000_records!$G:K,MTD!G$1,ecommerce_sales_1000_records!$C:G,MTD!$A3) -> 61141.17 | H3: =SUMIFS(ecommerce_sales_1000_records!$E:J,ecommerce_sales_1000_records!$G:L,MTD!H$1,ecommerce_sales_1000_records!$C:H,MTD!$A3) -> 114777.22 | I3: =SUMIFS(ecommerce_sales_1000_records!$E:K,ecommerce_sales_1000_records!$G:M,MTD!I$1,ecommerce_sales_1000_records!$C:I,MTD!$A3) -> 0 | J3: =SUMIFS(ecommerce_sales_1000_records!$E:L,ecommerce_sales_1000_records!$G:N,MTD!J$1,ecommerce_sales_1000_records!$C:J,MTD!$A3) -> 27684.6 | K3: =SUMIFS(ecommerce_sales_1000_records!$E:M,ecommerce_sales_1000_records!$G:O,MTD!K$1,ecommerce_sales_1000_records!$C:K,MTD!$A3) -> 81539.12 | L3: =SUMIFS(ecommerce_sales_1000_records!$E:N,ecommerce_sales_1000_records!$G:P,MTD!L$1,ecommerce_sales_1000_records!$C:L,MTD!$A3) -> 25774.8 | M3: =SUMIFS(ecommerce_sales_1000_records!$E:O,ecommerce_sales_1000_records!$G:Q,MTD!M$1,ecommerce_sales_1000_records!$C:M,MTD!$A3) -> 72650.23 | N3: =SUMIFS(ecommerce_sales_1000_records!$E:P,ecommerce_sales_1000_records!$G:R,MTD!N$1,ecommerce_sales_1000_records!$C:N,MTD!$A3) -> 50195.61 | O3: =SUMIFS(ecommerce_sales_1000_records!$E:Q,ecommerce_sales_1000_records!$G:S,MTD!O$1,ecommerce_sales_1000_records!$C:O,MTD!$A3) -> 16641.1 | P3: =SUMIFS(ecommerce_sales_1000_records!$E:R,ecommerce_sales_1000_records!$G:T,MTD!P$1,ecommerce_sales_1000_records!$C:P,MTD!$A3) -> 46596.67 | Q3: =SUMIFS(ecommerce_sales_1000_records!$E:S,ecommerce_sales_1000_records!$G:U,MTD!Q$1,ecommerce_sales_1000_records!$C:Q,MTD!$A3) -> 25541.36 | R3: =SUMIFS(ecommerce_sales_1000_records!$E:T,ecommerce_sales_1000_records!$G:V,MTD!R$1,ecommerce_sales_1000_records!$C:R,MTD!$A3) -> 0 | S3: =SUMIFS(ecommerce_sales_1000_records!$E:U,ecommerce_sales_1000_records!$G:W,MTD!S$1,ecommerce_sales_1000_records!$C:S,MTD!$A3) -> 0 | T3: =SUMIFS(ecommerce_sales_1000_records!$E:V,ecommerce_sales_1000_records!$G:X,MTD!T$1,ecommerce_sales_1000_records!$C:T,MTD!$A3) -> 107494.87 | U3: =SUMIFS(ecommerce_sales_1000_records!$E:W,ecommerce_sales_1000_records!$G:Y,MTD!U$1,ecommerce_sales_1000_records!$C:U,MTD!$A3) -> 144208.21 | V3: =SUMIFS(ecommerce_sales_1000_records!$E:X,ecommerce_sales_1000_records!$G:Z,MTD!V$1,ecommerce_sales_1000_records!$C:V,MTD!$A3) -> 90186.18 | W3: =SUMIFS(ecommerce_sales_1000_records!$E:Y,ecommerce_sales_1000_records!$G:AA,MTD!W$1,ecommerce_sales_1000_records!$C:W,MTD!$A3) -> 3810.2 | X3: =SUMIFS(ecommerce_sales_1000_records!$E:Z,ecommerce_sales_1000_records!$G:AB,MTD!X$1,ecommerce_sales_1000_records!$C:X,MTD!$A3) -> 80616.57 | Y3: =SUMIFS(ecommerce_sales_1000_records!$E:AA,ecommerce_sales_1000_records!$G:AC,MTD!Y$1,ecommerce_sales_1000_records!$C:Y,MTD!$A3) -> 1570.94 | Z3: =SUMIFS(ecommerce_sales_1000_records!$E:AB,ecommerce_sales_1000_records!$G:AD,MTD!Z$1,ecommerce_sales_1000_records!$C:Z,MTD!$A3) -> 0 | AA3: =SUMIFS(ecommerce_sales_1000_records!$E:AC,ecommerce_sales_1000_records!$G:AE,MTD!AA$1,ecommerce_sales_1000_records!$C:AA,MTD!$A3) -> 17818.55 | AB3: =SUMIFS(ecommerce_sales_1000_records!$E:AD,ecommerce_sales_1000_records!$G:AF,MTD!AB$1,ecommerce_sales_1000_records!$C:AB,MTD!$A3) -> 0 | AC3: =SUMIFS(ecommerce_sales_1000_records!$E:AE,ecommerce_sales_1000_records!$G:AG,MTD!AC$1,ecommerce_sales_1000_records!$C:AC,MTD!$A3) -> 115436.6 | AD3: =SUMIFS(ecommerce_sales_1000_records!$E:AF,ecommerce_sales_1000_records!$G:AH,MTD!AD$1,ecommerce_sales_1000_records!$C:AD,MTD!$A3) -> 71299.45 | AE3: =SUMIFS(ecommerce_sales_1000_records!$E:AG,ecommerce_sales_1000_records!$G:AI,MTD!AE$1,ecommerce_sales_1000_records!$C:AE,MTD!$A3) -> 55952.7 | AF3: =SUMIFS(ecommerce_sales_1000_records!$E:AH,ecommerce_sales_1000_records!$G:AJ,MTD!AF$1,ecommerce_sales_1000_records!$C:AF,MTD!$A3) -> 50448.34 | AG3: =SUMIFS(ecommerce_sales_1000_records!$E:AI,ecommerce_sales_1000_records!$G:AK,MTD!AG$1,ecommerce_sales_1000_records!$C:AG,MTD!$A3) -> 19664.91
A4: Books | B4: =SUM(C4:AG4) -> 6033.74 | C4: =SUMIFS(ecommerce_sales_1000_records!$E:E,ecommerce_sales_1000_records!$G:G,MTD!C$1,ecommerce_sales_1000_records!$C:C,MTD!$A4) -> 0 | D4: =SUMIFS(ecommerce_sales_1000_records!$E:F,ecommerce_sales_1000_records!$G:H,MTD!D$1,ecommerce_sales_1000_records!$C:D,MTD!$A4) -> 425.71 | E4: =SUMIFS(ecommerce_sales_1000_records!$E:G,ecommerce_sales_1000_records!$G:I,MTD!E$1,ecommerce_sales_1000_records!$C:E,MTD!$A4) -> 0 | F4: =SUMIFS(ecommerce_sales_1000_records!$E:H,ecommerce_sales_1000_records!$G:J,MTD!F$1,ecommerce_sales_1000_records!$C:F,MTD!$A4) -> 0 | G4: =SUMIFS(ecommerce_sales_1000_records!$E:I,ecommerce_sales_1000_records!$G:K,MTD!G$1,ecommerce_sales_1000_records!$C:G,MTD!$A4) -> 0 | H4: =SUMIFS(ecommerce_sales_1000_records!$E:J,ecommerce_sales_1000_records!$G:L,MTD!H$1,ecommerce_sales_1000_records!$C:H,MTD!$A4) -> 0 | I4: =SUMIFS(ecommerce_sales_1000_records!$E:K,ecommerce_sales_1000_records!$G:M,MTD!I$1,ecommerce_sales_1000_records!$C:I,MTD!$A4) -> 0 | J4: =SUMIFS(ecommerce_sales_1000_records!$E:L,ecommerce_sales_1000_records!$G:N,MTD!J$1,ecommerce_sales_1000_records!$C:J,MTD!$A4) -> 0 | K4: =SUMIFS(ecommerce_sales_1000_records!$E:M,ecommerce_sales_1000_records!$G:O,MTD!K$1,ecommerce_sales_1000_records!$C:K,MTD!$A4) -> 489.51 | L4: =SUMIFS(ecommerce_sales_1000_records!$E:N,ecommerce_sales_1000_records!$G:P,MTD!L$1,ecommerce_sales_1000_records!$C:L,MTD!$A4) -> 466.27 | M4: =SUMIFS(ecommerce_sales_1000_records!$E:O,ecommerce_sales_1000_records!$G:Q,MTD!M$1,ecommerce_sales_1000_records!$C:M,MTD!$A4) -> 476.66 | N4: =SUMIFS(ecommerce_sales_1000_records!$E:P,ecommerce_sales_1000_records!$G:R,MTD!N$1,ecommerce_sales_1000_records!$C:N,MTD!$A4) -> 932.91 | O4: =SUMIFS(ecommerce_sales_1000_records!$E:Q,ecommerce_sales_1000_records!$G:S,MTD!O$1,ecommerce_sales_1000_records!$C:O,MTD!$A4) -> 0 | P4: =SUMIFS(ecommerce_sales_1000_records!$E:R,ecommerce_sales_1000_records!$G:T,MTD!P$1,ecommerce_sales_1000_records!$C:P,MTD!$A4) -> 0 | Q4: =SUMIFS(ecommerce_sales_1000_records!$E:S,ecommerce_sales_1000_records!$G:U,MTD!Q$1,ecommerce_sales_1000_records!$C:Q,MTD!$A4) -> 0 | R4: =SUMIFS(ecommerce_sales_1000_records!$E:T,ecommerce_sales_1000_records!$G:V,MTD!R$1,ecommerce_sales_1000_records!$C:R,MTD!$A4) -> 0 | S4: =SUMIFS(ecommerce_sales_1000_records!$E:U,ecommerce_sales_1000_records!$G:W,MTD!S$1,ecommerce_sales_1000_records!$C:S,MTD!$A4) -> 476.03 | T4: =SUMIFS(ecommerce_sales_1000_records!$E:V,ecommerce_sales_1000_records!$G:X,MTD!T$1,ecommerce_sales_1000_records!$C:T,MTD!$A4) -> 472.17 | U4: =SUMIFS(ecommerce_sales_1000_records!$E:W,ecommerce_sales_1000_records!$G:Y,MTD!U$1,ecommerce_sales_1000_records!$C:U,MTD!$A4) -> 0 | V4: =SUMIFS(ecommerce_sales_1000_records!$E:X,ecommerce_sales_1000_records!$G:Z,MTD!V$1,ecommerce_sales_1000_records!$C:V,MTD!$A4) -> 0 | W4: =SUMIFS(ecommerce_sales_1000_records!$E:Y,ecommerce_sales_1000_records!$G:AA,MTD!W$1,ecommerce_sales_1000_records!$C:W,MTD!$A4) -> 0 | X4: =SUMIFS(ecommerce_sales_1000_records!$E:Z,ecommerce_sales_1000_records!$G:AB,MTD!X$1,ecommerce_sales_1000_records!$C:X,MTD!$A4) -> 440.47 | Y4: =SUMIFS(ecommerce_sales_1000_records!$E:AA,ecommerce_sales_1000_records!$G:AC,MTD!Y$1,ecommerce_sales_1000_records!$C:Y,MTD!$A4) -> 0 | Z4: =SUMIFS(ecommerce_sales_1000_records!$E:AB,ecommerce_sales_1000_records!$G:AD,MTD!Z$1,ecommerce_sales_1000_records!$C:Z,MTD!$A4) -> 0 | AA4: =SUMIFS(ecommerce_sales_1000_records!$E:AC,ecommerce_sales_1000_records!$G:AE,MTD!AA$1,ecommerce_sales_1000_records!$C:AA,MTD!$A4) -> 0 | AB4: =SUMIFS(ecommerce_sales_1000_records!$E:AD,ecommerce_sales_1000_records!$G:AF,MTD!AB$1,ecommerce_sales_1000_records!$C:AB,MTD!$A4) -> 482.4 | AC4: =SUMIFS(ecommerce_sales_1000_records!$E:AE,ecommerce_sales_1000_records!$G:AG,MTD!AC$1,ecommerce_sales_1000_records!$C:AC,MTD!$A4) -> 454.09 | AD4: =SUMIFS(ecommerce_sales_1000_records!$E:AF,ecommerce_sales_1000_records!$G:AH,MTD!AD$1,ecommerce_sales_1000_records!$C:AD,MTD!$A4) -> 0 | AE4: =SUMIFS(ecommerce_sales_1000_records!$E:AG,ecommerce_sales_1000_records!$G:AI,MTD!AE$1,ecommerce_sales_1000_records!$C:AE,MTD!$A4) -> 452.03 | AF4: =SUMIFS(ecommerce_sales_1000_records!$E:AH,ecommerce_sales_1000_records!$G:AJ,MTD!AF$1,ecommerce_sales_1000_records!$C:AF,MTD!$A4) -> 0 | AG4: =SUMIFS(ecommerce_sales_1000_records!$E:AI,ecommerce_sales_1000_records!$G:AK,MTD!AG$1,ecommerce_sales_1000_records!$C:AG,MTD!$A4) -> 465.49
A5: Fashion | B5: =SUM(C5:AG5) -> 65031.48 | C5: =SUMIFS(ecommerce_sales_1000_records!$E:E,ecommerce_sales_1000_records!$G:G,MTD!C$1,ecommerce_sales_1000_records!$C:C,MTD!$A5) -> 4658 | D5: =SUMIFS(ecommerce_sales_1000_records!$E:F,ecommerce_sales_1000_records!$G:H,MTD!D$1,ecommerce_sales_1000_records!$C:D,MTD!$A5) -> 1914.82 | E5: =SUMIFS(ecommerce_sales_1000_records!$E:G,ecommerce_sales_1000_records!$G:I,MTD!E$1,ecommerce_sales_1000_records!$C:E,MTD!$A5) -> 766.73 | F5: =SUMIFS(ecommerce_sales_1000_records!$E:H,ecommerce_sales_1000_records!$G:J,MTD!F$1,ecommerce_sales_1000_records!$C:F,MTD!$A5) -> 2185.24 | G5: =SUMIFS(ecommerce_sales_1000_records!$E:I,ecommerce_sales_1000_records!$G:K,MTD!G$1,ecommerce_sales_1000_records!$C:G,MTD!$A5) -> 1865.02 | H5: =SUMIFS(ecommerce_sales_1000_records!$E:J,ecommerce_sales_1000_records!$G:L,MTD!H$1,ecommerce_sales_1000_records!$C:H,MTD!$A5) -> 2396.98 | I5: =SUMIFS(ecommerce_sales_1000_records!$E:K,ecommerce_sales_1000_records!$G:M,MTD!I$1,ecommerce_sales_1000_records!$C:I,MTD!$A5) -> 847.99 | J5: =SUMIFS(ecommerce_sales_1000_records!$E:L,ecommerce_sales_1000_records!$G:N,MTD!J$1,ecommerce_sales_1000_records!$C:J,MTD!$A5) -> 0 | K5: =SUMIFS(ecommerce_sales_1000_records!$E:M,ecommerce_sales_1000_records!$G:O,MTD!K$1,ecommerce_sales_1000_records!$C:K,MTD!$A5) -> 3744.79 | L5: =SUMIFS(ecommerce_sales_1000_records!$E:N,ecommerce_sales_1000_records!$G:P,MTD!L$1,ecommerce_sales_1000_records!$C:L,MTD!$A5) -> 5556.19 | M5: =SUMIFS(ecommerce_sales_1000_records!$E:O,ecommerce_sales_1000_records!$G:Q,MTD!M$1,ecommerce_sales_1000_records!$C:M,MTD!$A5) -> 3430.55 | N5: =SUMIFS(ecommerce_sales_1000_records!$E:P,ecommerce_sales_1000_records!$G:R,MTD!N$1,ecommerce_sales_1000_records!$C:N,MTD!$A5) -> 0 | O5: =SUMIFS(ecommerce_sales_1000_records!$E:Q,ecommerce_sales_1000_records!$G:S,MTD!O$1,ecommerce_sales_1000_records!$C:O,MTD!$A5) -> 0 | P5: =SUMIFS(ecommerce_sales_1000_records!$E:R,ecommerce_sales_1000_records!$G:T,MTD!P$1,ecommerce_sales_1000_records!$C:P,MTD!$A5) -> 0 | Q5: =SUMIFS(ecommerce_sales_1000_records!$E:S,ecommerce_sales_1000_records!$G:U,MTD!Q$1,ecommerce_sales_1000_records!$C:Q,MTD!$A5) -> 797.47 | R5: =SUMIFS(ecommerce_sales_1000_records!$E:T,ecommerce_sales_1000_records!$G:V,MTD!R$1,ecommerce_sales_1000_records!$C:R,MTD!$A5) -> 2708.31 | S5: =SUMIFS(ecommerce_sales_1000_records!$E:U,ecommerce_sales_1000_records!$G:W,MTD!S$1,ecommerce_sales_1000_records!$C:S,MTD!$A5) -> 2679.45 | T5: =SUMIFS(ecommerce_sales_1000_records!$E:V,ecommerce_sales_1000_records!$G:X,MTD!T$1,ecommerce_sales_1000_records!$C:T,MTD!$A5) -> 5390.28 | U5: =SUMIFS(ecommerce_sales_1000_records!$E:W,ecommerce_sales_1000_records!$G:Y,MTD!U$1,ecommerce_sales_1000_records!$C:U,MTD!$A5) -> 4944.94 | V5: =SUMIFS(ecommerce_sales_1000_records!$E:X,ecommerce_sales_1000_records!$G:Z,MTD!V$1,ecommerce_sales_1000_records!$C:V,MTD!$A5) -> 2692.89 | W5: =SUMIFS(ecommerce_sales_1000_records!$E:Y,ecommerce_sales_1000_records!$G:AA,MTD!W$1,ecommerce_sales_1000_records!$C:W,MTD!$A5) -> 2708.2 | X5: =SUMIFS(ecommerce_sales_1000_records!$E:Z,ecommerce_sales_1000_records!$G:AB,MTD!X$1,ecommerce_sales_1000_records!$C:X,MTD!$A5) -> 0 | Y5: =SUMIFS(ecommerce_sales_1000_records!$E:AA,ecommerce_sales_1000_records!$G:AC,MTD!Y$1,ecommerce_sales_1000_records!$C:Y,MTD!$A5) -> 864.65 | Z5: =SUMIFS(ecommerce_sales_1000_records!$E:AB,ecommerce_sales_1000_records!$G:AD,MTD!Z$1,ecommerce_sales_1000_records!$C:Z,MTD!$A5) -> 3487.9 | AA5: =SUMIFS(ecommerce_sales_1000_records!$E:AC,ecommerce_sales_1000_records!$G:AE,MTD!AA$1,ecommerce_sales_1000_records!$C:AA,MTD!$A5) -> 0 | AB5: =SUMIFS(ecommerce_sales_1000_records!$E:AD,ecommerce_sales_1000_records!$G:AF,MTD!AB$1,ecommerce_sales_1000_records!$C:AB,MTD!$A5) -> 7467.16 | AC5: =SUMIFS(ecommerce_sales_1000_records!$E:AE,ecommerce_sales_1000_records!$G:AG,MTD!AC$1,ecommerce_sales_1000_records!$C:AC,MTD!$A5) -> 1887.41 | AD5: =SUMIFS(ecommerce_sales_1000_records!$E:AF,ecommerce_sales_1000_records!$G:AH,MTD!AD$1,ecommerce_sales_1000_records!$C:AD,MTD!$A5) -> 2036.51 | AE5: =SUMIFS(ecommerce_sales_1000_records!$E:AG,ecommerce_sales_1000_records!$G:AI,MTD!AE$1,ecommerce_sales_1000_records!$C:AE,MTD!$A5) -> 0 | AF5: =SUMIFS(ecommerce_sales_1000_records!$E:AH,ecommerce_sales_1000_records!$G:AJ,MTD!AF$1,ecommerce_sales_1000_records!$C:AF,MTD!$A5) -> 0 | AG5: =SUMIFS(ecommerce_sales_1000_records!$E:AI,ecommerce_sales_1000_records!$G:AK,MTD!AG$1,ecommerce_sales_1000_records!$C:AG,MTD!$A5) -> 0
A6: Home Appliances | B6: =SUM(C6:AG6) -> 154798.52 | C6: =SUMIFS(ecommerce_sales_1000_records!$E:E,ecommerce_sales_1000_records!$G:G,MTD!C$1,ecommerce_sales_1000_records!$C:C,MTD!$A6) -> 4391.4 | D6: =SUMIFS(ecommerce_sales_1000_records!$E:F,ecommerce_sales_1000_records!$G:H,MTD!D$1,ecommerce_sales_1000_records!$C:D,MTD!$A6) -> 3898.75 | E6: =SUMIFS(ecommerce_sales_1000_records!$E:G,ecommerce_sales_1000_records!$G:I,MTD!E$1,ecommerce_sales_1000_records!$C:E,MTD!$A6) -> 0 | F6: =SUMIFS(ecommerce_sales_1000_records!$E:H,ecommerce_sales_1000_records!$G:J,MTD!F$1,ecommerce_sales_1000_records!$C:F,MTD!$A6) -> 3218.54 | G6: =SUMIFS(ecommerce_sales_1000_records!$E:I,ecommerce_sales_1000_records!$G:K,MTD!G$1,ecommerce_sales_1000_records!$C:G,MTD!$A6) -> 0 | H6: =SUMIFS(ecommerce_sales_1000_records!$E:J,ecommerce_sales_1000_records!$G:L,MTD!H$1,ecommerce_sales_1000_records!$C:H,MTD!$A6) -> 0 | I6: =SUMIFS(ecommerce_sales_1000_records!$E:K,ecommerce_sales_1000_records!$G:M,MTD!I$1,ecommerce_sales_1000_records!$C:I,MTD!$A6) -> 13295.39 | J6: =SUMIFS(ecommerce_sales_1000_records!$E:L,ecommerce_sales_1000_records!$G:N,MTD!J$1,ecommerce_sales_1000_records!$C:J,MTD!$A6) -> 0 | K6: =SUMIFS(ecommerce_sales_1000_records!$E:M,ecommerce_sales_1000_records!$G:O,MTD!K$1,ecommerce_sales_1000_records!$C:K,MTD!$A6) -> 0 | L6: =SUMIFS(ecommerce_sales_1000_records!$E:N,ecommerce_sales_1000_records!$G:P,MTD!L$1,ecommerce_sales_1000_records!$C:L,MTD!$A6) -> 0 | M6: =SUMIFS(ecommerce_sales_1000_records!$E:O,ecommerce_sales_1000_records!$G:Q,MTD!M$1,ecommerce_sales_1000_records!$C:M,MTD!$A6) -> 7367.59 | N6: =SUMIFS(ecommerce_sales_1000_records!$E:P,ecommerce_sales_1000_records!$G:R,MTD!N$1,ecommerce_sales_1000_records!$C:N,MTD!$A6) -> 3771.32 | O6: =SUMIFS(ecommerce_sales_1000_records!$E:Q,ecommerce_sales_1000_records!$G:S,MTD!O$1,ecommerce_sales_1000_records!$C:O,MTD!$A6) -> 0 | P6: =SUMIFS(ecommerce_sales_1000_records!$E:R,ecommerce_sales_1000_records!$G:T,MTD!P$1,ecommerce_sales_1000_records!$C:P,MTD!$A6) -> 19957.63 | Q6: =SUMIFS(ecommerce_sales_1000_records!$E:S,ecommerce_sales_1000_records!$G:U,MTD!Q$1,ecommerce_sales_1000_records!$C:Q,MTD!$A6) -> 7486.65 | R6: =SUMIFS(ecommerce_sales_1000_records!$E:T,ecommerce_sales_1000_records!$G:V,MTD!R$1,ecommerce_sales_1000_records!$C:R,MTD!$A6) -> 14318.42 | S6: =SUMIFS(ecommerce_sales_1000_records!$E:U,ecommerce_sales_1000_records!$G:W,MTD!S$1,ecommerce_sales_1000_records!$C:S,MTD!$A6) -> 0 | T6: =SUMIFS(ecommerce_sales_1000_records!$E:V,ecommerce_sales_1000_records!$G:X,MTD!T$1,ecommerce_sales_1000_records!$C:T,MTD!$A6) -> 0 | U6: =SUMIFS(ecommerce_sales_1000_records!$E:W,ecommerce_sales_1000_records!$G:Y,MTD!U$1,ecommerce_sales_1000_records!$C:U,MTD!$A6) -> 10601.16 | V6: =SUMIFS(ecommerce_sales_1000_records!$E:X,ecommerce_sales_1000_records!$G:Z,MTD!V$1,ecommerce_sales_1000_records!$C:V,MTD!$A6) -> 8224.79 | W6: =SUMIFS(ecommerce_sales_1000_records!$E:Y,ecommerce_sales_1000_records!$G:AA,MTD!W$1,ecommerce_sales_1000_records!$C:W,MTD!$A6) -> 12743.97 | X6: =SUMIFS(ecommerce_sales_1000_records!$E:Z,ecommerce_sales_1000_records!$G:AB,MTD!X$1,ecommerce_sales_1000_records!$C:X,MTD!$A6) -> 0 | Y6: =SUMIFS(ecommerce_sales_1000_records!$E:AA,ecommerce_sales_1000_records!$G:AC,MTD!Y$1,ecommerce_sales_1000_records!$C:Y,MTD!$A6) -> 9977.99 | Z6: =SUMIFS(ecommerce_sales_1000_records!$E:AB,ecommerce_sales_1000_records!$G:AD,MTD!Z$1,ecommerce_sales_1000_records!$C:Z,MTD!$A6) -> 3463.72 | AA6: =SUMIFS(ecommerce_sales_1000_records!$E:AC,ecommerce_sales_1000_records!$G:AE,MTD!AA$1,ecommerce_sales_1000_records!$C:AA,MTD!$A6) -> 6524.83 | AB6: =SUMIFS(ecommerce_sales_1000_records!$E:AD,ecommerce_sales_1000_records!$G:AF,MTD!AB$1,ecommerce_sales_1000_records!$C:AB,MTD!$A6) -> 0 | AC6: =SUMIFS(ecommerce_sales_1000_records!$E:AE,ecommerce_sales_1000_records!$G:AG,MTD!AC$1,ecommerce_sales_1000_records!$C:AC,MTD!$A6) -> 3989.88 | AD6: =SUMIFS(ecommerce_sales_1000_records!$E:AF,ecommerce_sales_1000_records!$G:AH,MTD!AD$1,ecommerce_sales_1000_records!$C:AD,MTD!$A6) -> 13528.43 | AE6: =SUMIFS(ecommerce_sales_1000_records!$E:AG,ecommerce_sales_1000_records!$G:AI,MTD!AE$1,ecommerce_sales_1000_records!$C:AE,MTD!$A6) -> 0 | AF6: =SUMIFS(ecommerce_sales_1000_records!$E:AH,ecommerce_sales_1000_records!$G:AJ,MTD!AF$1,ecommerce_sales_1000_records!$C:AF,MTD!$A6) -> 4617.17 | AG6: =SUMIFS(ecommerce_sales_1000_records!$E:AI,ecommerce_sales_1000_records!$G:AK,MTD!AG$1,ecommerce_sales_1000_records!$C:AG,MTD!$A6) -> 3420.89
A7: Total Sales : | B7: =SUM(B2:B6) -> 1811770.1 | C7: =SUM(C2:C6) -> 50325.97 | D7: =SUM(D2:D6) -> 96258.73 | E7: =SUM(E2:E6) -> 28283.32 | F7: =SUM(F2:F6) -> 87576.59 | G7: =SUM(G2:G6) -> 63006.19 | H7: =SUM(H2:H6) -> 117174.2 | I7: =SUM(I2:I6) -> 14143.38 | ... AG7: =SUM(AG2:AG6) -> 25174.63
A9: Date | B9: 46054 | C9: 46054 | D9: =C9+1 -> 46055 | E9: =D9+1 -> 46056 | F9: =E9+1 -> 46057 | G9: =F9+1 -> 46058 | H9: =G9+1 -> 46059 | I9: =H9+1 -> 46060 | J9: =I9+1 -> 46061 | K9: =J9+1 -> 46062 | ... AD9: =AC9+1 -> 46081
A10: Accessories | B10: =SUM(C10:AG10) -> 99356.48 | C10: =SUMIFS(ecommerce_sales_1000_records!$E:E,ecommerce_sales_1000_records!$G:G,C$9,ecommerce_sales_1000_records!$C:C,MTD!$A10) -> 5409.63 | D10: =SUMIFS(ecommerce_sales_1000_records!$E:F,ecommerce_sales_1000_records!$G:H,D$9,ecommerce_sales_1000_records!$C:D,MTD!$A10) -> 12353.54 | E10: =SUMIFS(ecommerce_sales_1000_records!$E:G,ecommerce_sales_1000_records!$G:I,E$9,ecommerce_sales_1000_records!$C:E,MTD!$A10) -> 1935.5 | F10: =SUMIFS(ecommerce_sales_1000_records!$E:H,ecommerce_sales_1000_records!$G:J,F$9,ecommerce_sales_1000_records!$C:F,MTD!$A10) -> 5469.4 | G10: =SUMIFS(ecommerce_sales_1000_records!$E:I,ecommerce_sales_1000_records!$G:K,G$9,ecommerce_sales_1000_records!$C:G,MTD!$A10) -> 1649.51 | H10: =SUMIFS(ecommerce_sales_1000_records!$E:J,ecommerce_sales_1000_records!$G:L,H$9,ecommerce_sales_1000_records!$C:H,MTD!$A10) -> 0 | I10: =SUMIFS(ecommerce_sales_1000_records!$E:K,ecommerce_sales_1000_records!$G:M,I$9,ecommerce_sales_1000_records!$C:I,MTD!$A10) -> 1898.86 | J10: =SUMIFS(ecommerce_sales_1000_records!$E:L,ecommerce_sales_1000_records!$G:N,J$9,ecommerce_sales_1000_records!$C:J,MTD!$A10) -> 4980.93 | K10: =SUMIFS(ecommerce_sales_1000_records!$E:M,ecommerce_sales_1000_records!$G:O,K$9,ecommerce_sales_1000_records!$C:K,MTD!$A10) -> 12042.54 | L10: =SUMIFS(ecommerce_sales_1000_records!$E:N,ecommerce_sales_1000_records!$G:P,L$9,ecommerce_sales_1000_records!$C:L,MTD!$A10) -> 1660.7 | M10: =SUMIFS(ecommerce_sales_1000_records!$E:O,ecommerce_sales_1000_records!$G:Q,M$9,ecommerce_sales_1000_records!$C:M,MTD!$A10) -> 6632.38 | N10: =SUMIFS(ecommerce_sales_1000_records!$E:P,ecommerce_sales_1000_records!$G:R,N$9,ecommerce_sales_1000_records!$C:N,MTD!$A10) -> 0 | O10: =SUMIFS(ecommerce_sales_1000_records!$E:Q,ecommerce_sales_1000_records!$G:S,O$9,ecommerce_sales_1000_records!$C:O,MTD!$A10) -> 0 | P10: =SUMIFS(ecommerce_sales_1000_records!$E:R,ecommerce_sales_1000_records!$G:T,P$9,ecommerce_sales_1000_records!$C:P,MTD!$A10) -> 0 | Q10: =SUMIFS(ecommerce_sales_1000_records!$E:S,ecommerce_sales_1000_records!$G:U,Q$9,ecommerce_sales_1000_records!$C:Q,MTD!$A10) -> 4981.94 | R10: =SUMIFS(ecommerce_sales_1000_records!$E:T,ecommerce_sales_1000_records!$G:V,R$9,ecommerce_sales_1000_records!$C:R,MTD!$A10) -> 0 | S10: =SUMIFS(ecommerce_sales_1000_records!$E:U,ecommerce_sales_1000_records!$G:W,S$9,ecommerce_sales_1000_records!$C:S,MTD!$A10) -> 4648.29 | T10: =SUMIFS(ecommerce_sales_1000_records!$E:V,ecommerce_sales_1000_records!$G:X,T$9,ecommerce_sales_1000_records!$C:T,MTD!$A10) -> 1641.8 | U10: =SUMIFS(ecommerce_sales_1000_records!$E:W,ecommerce_sales_1000_records!$G:Y,U$9,ecommerce_sales_1000_records!$C:U,MTD!$A10) -> 0 | V10: =SUMIFS(ecommerce_sales_1000_records!$E:X,ecommerce_sales_1000_records!$G:Z,V$9,ecommerce_sales_1000_records!$C:V,MTD!$A10) -> 0 | W10: =SUMIFS(ecommerce_sales_1000_records!$E:Y,ecommerce_sales_1000_records!$G:AA,W$9,ecommerce_sales_1000_records!$C:W,MTD!$A10) -> 0 | X10: =SUMIFS(ecommerce_sales_1000_records!$E:Z,ecommerce_sales_1000_records!$G:AB,X$9,ecommerce_sales_1000_records!$C:X,MTD!$A10) -> 14171.33 | Y10: =SUMIFS(ecommerce_sales_1000_records!$E:AA,ecommerce_sales_1000_records!$G:AC,Y$9,ecommerce_sales_1000_records!$C:Y,MTD!$A10) -> 5032.18 | Z10: =SUMIFS(ecommerce_sales_1000_records!$E:AB,ecommerce_sales_1000_records!$G:AD,Z$9,ecommerce_sales_1000_records!$C:Z,MTD!$A10) -> 1873.33 | AA10: =SUMIFS(ecommerce_sales_1000_records!$E:AC,ecommerce_sales_1000_records!$G:AE,AA$9,ecommerce_sales_1000_records!$C:AA,MTD!$A10) -> 0 | AB10: =SUMIFS(ecommerce_sales_1000_records!$E:AD,ecommerce_sales_1000_records!$G:AF,AB$9,ecommerce_sales_1000_records!$C:AB,MTD!$A10) -> 9145.46 | AC10: =SUMIFS(ecommerce_sales_1000_records!$E:AE,ecommerce_sales_1000_records!$G:AG,AC$9,ecommerce_sales_1000_records!$C:AC,MTD!$A10) -> 1905.73 | AD10: =SUMIFS(ecommerce_sales_1000_records!$E:AF,ecommerce_sales_1000_records!$G:AH,AD$9,ecommerce_sales_1000_records!$C:AD,MTD!$A10) -> 1923.43
A11: Electronics | B11: =SUM(C11:AG11) -> 1044268.1 | C11: =SUMIFS(ecommerce_sales_1000_records!$E:E,ecommerce_sales_1000_records!$G:G,C$9,ecommerce_sales_1000_records!$C:C,MTD!$A11) -> 44869.68 | D11: =SUMIFS(ecommerce_sales_1000_records!$E:F,ecommerce_sales_1000_records!$G:H,D$9,ecommerce_sales_1000_records!$C:D,MTD!$A11) -> 51675.25 | E11: =SUMIFS(ecommerce_sales_1000_records!$E:G,ecommerce_sales_1000_records!$G:I,E$9,ecommerce_sales_1000_records!$C:E,MTD!$A11) -> 88395.01 | F11: =SUMIFS(ecommerce_sales_1000_records!$E:H,ecommerce_sales_1000_records!$G:J,F$9,ecommerce_sales_1000_records!$C:F,MTD!$A11) -> 86719.67 | G11: =SUMIFS(ecommerce_sales_1000_records!$E:I,ecommerce_sales_1000_records!$G:K,G$9,ecommerce_sales_1000_records!$C:G,MTD!$A11) -> 55306.63 | H11: =SUMIFS(ecommerce_sales_1000_records!$E:J,ecommerce_sales_1000_records!$G:L,H$9,ecommerce_sales_1000_records!$C:H,MTD!$A11) -> 80869.43 | I11: =SUMIFS(ecommerce_sales_1000_records!$E:K,ecommerce_sales_1000_records!$G:M,I$9,ecommerce_sales_1000_records!$C:I,MTD!$A11) -> 30081.01 | J11: =SUMIFS(ecommerce_sales_1000_records!$E:L,ecommerce_sales_1000_records!$G:N,J$9,ecommerce_sales_1000_records!$C:J,MTD!$A11) -> 50098.03 | K11: =SUMIFS(ecommerce_sales_1000_records!$E:M,ecommerce_sales_1000_records!$G:O,K$9,ecommerce_sales_1000_records!$C:K,MTD!$A11) -> 21260.61 | L11: =SUMIFS(ecommerce_sales_1000_records!$E:N,ecommerce_sales_1000_records!$G:P,L$9,ecommerce_sales_1000_records!$C:L,MTD!$A11) -> 84884.7 | M11: =SUMIFS(ecommerce_sales_1000_records!$E:O,ecommerce_sales_1000_records!$G:Q,M$9,ecommerce_sales_1000_records!$C:M,MTD!$A11) -> 1561.03 | N11: =SUMIFS(ecommerce_sales_1000_records!$E:P,ecommerce_sales_1000_records!$G:R,N$9,ecommerce_sales_1000_records!$C:N,MTD!$A11) -> 55880.26 | O11: =SUMIFS(ecommerce_sales_1000_records!$E:Q,ecommerce_sales_1000_records!$G:S,O$9,ecommerce_sales_1000_records!$C:O,MTD!$A11) -> 1506.33 | P11: =SUMIFS(ecommerce_sales_1000_records!$E:R,ecommerce_sales_1000_records!$G:T,P$9,ecommerce_sales_1000_records!$C:P,MTD!$A11) -> 2366.91 | Q11: =SUMIFS(ecommerce_sales_1000_records!$E:S,ecommerce_sales_1000_records!$G:U,Q$9,ecommerce_sales_1000_records!$C:Q,MTD!$A11) -> 1530.72 | R11: =SUMIFS(ecommerce_sales_1000_records!$E:T,ecommerce_sales_1000_records!$G:V,R$9,ecommerce_sales_1000_records!$C:R,MTD!$A11) -> 46180.33 | S11: =SUMIFS(ecommerce_sales_1000_records!$E:U,ecommerce_sales_1000_records!$G:W,S$9,ecommerce_sales_1000_records!$C:S,MTD!$A11) -> 2369.62 | T11: =SUMIFS(ecommerce_sales_1000_records!$E:V,ecommerce_sales_1000_records!$G:X,T$9,ecommerce_sales_1000_records!$C:T,MTD!$A11) -> 2969.23 | U11: =SUMIFS(ecommerce_sales_1000_records!$E:W,ecommerce_sales_1000_records!$G:Y,U$9,ecommerce_sales_1000_records!$C:U,MTD!$A11) -> 18087.79 | V11: =SUMIFS(ecommerce_sales_1000_records!$E:X,ecommerce_sales_1000_records!$G:Z,V$9,ecommerce_sales_1000_records!$C:V,MTD!$A11) -> 1530.61 | W11: =SUMIFS(ecommerce_sales_1000_records!$E:Y,ecommerce_sales_1000_records!$G:AA,W$9,ecommerce_sales_1000_records!$C:W,MTD!$A11) -> 17844.29 | X11: =SUMIFS(ecommerce_sales_1000_records!$E:Z,ecommerce_sales_1000_records!$G:AB,X$9,ecommerce_sales_1000_records!$C:X,MTD!$A11) -> 0 | Y11: =SUMIFS(ecommerce_sales_1000_records!$E:AA,ecommerce_sales_1000_records!$G:AC,Y$9,ecommerce_sales_1000_records!$C:Y,MTD!$A11) -> 2214.61 | Z11: =SUMIFS(ecommerce_sales_1000_records!$E:AB,ecommerce_sales_1000_records!$G:AD,Z$9,ecommerce_sales_1000_records!$C:Z,MTD!$A11) -> 87575.25 | AA11: =SUMIFS(ecommerce_sales_1000_records!$E:AC,ecommerce_sales_1000_records!$G:AE,AA$9,ecommerce_sales_1000_records!$C:AA,MTD!$A11) -> 50242.86 | AB11: =SUMIFS(ecommerce_sales_1000_records!$E:AD,ecommerce_sales_1000_records!$G:AF,AB$9,ecommerce_sales_1000_records!$C:AB,MTD!$A11) -> 29769.68 | AC11: =SUMIFS(ecommerce_sales_1000_records!$E:AE,ecommerce_sales_1000_records!$G:AG,AC$9,ecommerce_sales_1000_records!$C:AC,MTD!$A11) -> 80205.68 | AD11: =SUMIFS(ecommerce_sales_1000_records!$E:AF,ecommerce_sales_1000_records!$G:AH,AD$9,ecommerce_sales_1000_records!$C:AD,MTD!$A11) -> 48272.86
A12: Books | B12: =SUM(C12:AG12) -> 4974.32 | C12: =SUMIFS(ecommerce_sales_1000_records!$E:E,ecommerce_sales_1000_records!$G:G,C$9,ecommerce_sales_1000_records!$C:C,MTD!$A12) -> 487.91 | D12: =SUMIFS(ecommerce_sales_1000_records!$E:F,ecommerce_sales_1000_records!$G:H,D$9,ecommerce_sales_1000_records!$C:D,MTD!$A12) -> 0 | E12: =SUMIFS(ecommerce_sales_1000_records!$E:G,ecommerce_sales_1000_records!$G:I,E$9,ecommerce_sales_1000_records!$C:E,MTD!$A12) -> 0 | F12: =SUMIFS(ecommerce_sales_1000_records!$E:H,ecommerce_sales_1000_records!$G:J,F$9,ecommerce_sales_1000_records!$C:F,MTD!$A12) -> 412.56 | G12: =SUMIFS(ecommerce_sales_1000_records!$E:I,ecommerce_sales_1000_records!$G:K,G$9,ecommerce_sales_1000_records!$C:G,MTD!$A12) -> 0 | H12: =SUMIFS(ecommerce_sales_1000_records!$E:J,ecommerce_sales_1000_records!$G:L,H$9,ecommerce_sales_1000_records!$C:H,MTD!$A12) -> 0 | I12: =SUMIFS(ecommerce_sales_1000_records!$E:K,ecommerce_sales_1000_records!$G:M,I$9,ecommerce_sales_1000_records!$C:I,MTD!$A12) -> 477.04 | J12: =SUMIFS(ecommerce_sales_1000_records!$E:L,ecommerce_sales_1000_records!$G:N,J$9,ecommerce_sales_1000_records!$C:J,MTD!$A12) -> 0 | K12: =SUMIFS(ecommerce_sales_1000_records!$E:M,ecommerce_sales_1000_records!$G:O,K$9,ecommerce_sales_1000_records!$C:K,MTD!$A12) -> 0 | L12: =SUMIFS(ecommerce_sales_1000_records!$E:N,ecommerce_sales_1000_records!$G:P,L$9,ecommerce_sales_1000_records!$C:L,MTD!$A12) -> 484.5 | M12: =SUMIFS(ecommerce_sales_1000_records!$E:O,ecommerce_sales_1000_records!$G:Q,M$9,ecommerce_sales_1000_records!$C:M,MTD!$A12) -> 491.74 | N12: =SUMIFS(ecommerce_sales_1000_records!$E:P,ecommerce_sales_1000_records!$G:R,N$9,ecommerce_sales_1000_records!$C:N,MTD!$A12) -> 0 | O12: =SUMIFS(ecommerce_sales_1000_records!$E:Q,ecommerce_sales_1000_records!$G:S,O$9,ecommerce_sales_1000_records!$C:O,MTD!$A12) -> 0 | P12: =SUMIFS(ecommerce_sales_1000_records!$E:R,ecommerce_sales_1000_records!$G:T,P$9,ecommerce_sales_1000_records!$C:P,MTD!$A12) -> 878.25 | Q12: =SUMIFS(ecommerce_sales_1000_records!$E:S,ecommerce_sales_1000_records!$G:U,Q$9,ecommerce_sales_1000_records!$C:Q,MTD!$A12) -> 0 | R12: =SUMIFS(ecommerce_sales_1000_records!$E:T,ecommerce_sales_1000_records!$G:V,R$9,ecommerce_sales_1000_records!$C:R,MTD!$A12) -> 433.94 | S12: =SUMIFS(ecommerce_sales_1000_records!$E:U,ecommerce_sales_1000_records!$G:W,S$9,ecommerce_sales_1000_records!$C:S,MTD!$A12) -> 0 | T12: =SUMIFS(ecommerce_sales_1000_records!$E:V,ecommerce_sales_1000_records!$G:X,T$9,ecommerce_sales_1000_records!$C:T,MTD!$A12) -> 415.41 | U12: =SUMIFS(ecommerce_sales_1000_records!$E:W,ecommerce_sales_1000_records!$G:Y,U$9,ecommerce_sales_1000_records!$C:U,MTD!$A12) -> 0 | V12: =SUMIFS(ecommerce_sales_1000_records!$E:X,ecommerce_sales_1000_records!$G:Z,V$9,ecommerce_sales_1000_records!$C:V,MTD!$A12) -> 0 | W12: =SUMIFS(ecommerce_sales_1000_records!$E:Y,ecommerce_sales_1000_records!$G:AA,W$9,ecommerce_sales_1000_records!$C:W,MTD!$A12) -> 0 | X12: =SUMIFS(ecommerce_sales_1000_records!$E:Z,ecommerce_sales_1000_records!$G:AB,X$9,ecommerce_sales_1000_records!$C:X,MTD!$A12) -> 485.11 | Y12: =SUMIFS(ecommerce_sales_1000_records!$E:AA,ecommerce_sales_1000_records!$G:AC,Y$9,ecommerce_sales_1000_records!$C:Y,MTD!$A12) -> 0 | Z12: =SUMIFS(ecommerce_sales_1000_records!$E:AB,ecommerce_sales_1000_records!$G:AD,Z$9,ecommerce_sales_1000_records!$C:Z,MTD!$A12) -> 0 | AA12: =SUMIFS(ecommerce_sales_1000_records!$E:AC,ecommerce_sales_1000_records!$G:AE,AA$9,ecommerce_sales_1000_records!$C:AA,MTD!$A12) -> 407.86 | AB12: =SUMIFS(ecommerce_sales_1000_records!$E:AD,ecommerce_sales_1000_records!$G:AF,AB$9,ecommerce_sales_1000_records!$C:AB,MTD!$A12) -> 0 | AC12: =SUMIFS(ecommerce_sales_1000_records!$E:AE,ecommerce_sales_1000_records!$G:AG,AC$9,ecommerce_sales_1000_records!$C:AC,MTD!$A12) -> 0 | AD12: =SUMIFS(ecommerce_sales_1000_records!$E:AF,ecommerce_sales_1000_records!$G:AH,AD$9,ecommerce_sales_1000_records!$C:AD,MTD!$A12) -> 0
A13: Fashion | B13: =SUM(C13:AG13) -> 57796.06 | C13: =SUMIFS(ecommerce_sales_1000_records!$E:E,ecommerce_sales_1000_records!$G:G,C$9,ecommerce_sales_1000_records!$C:C,MTD!$A13) -> 0 | D13: =SUMIFS(ecommerce_sales_1000_records!$E:F,ecommerce_sales_1000_records!$G:H,D$9,ecommerce_sales_1000_records!$C:D,MTD!$A13) -> 7347.41 | E13: =SUMIFS(ecommerce_sales_1000_records!$E:G,ecommerce_sales_1000_records!$G:I,E$9,ecommerce_sales_1000_records!$C:E,MTD!$A13) -> 4260.96 | F13: =SUMIFS(ecommerce_sales_1000_records!$E:H,ecommerce_sales_1000_records!$G:J,F$9,ecommerce_sales_1000_records!$C:F,MTD!$A13) -> 2656.67 | G13: =SUMIFS(ecommerce_sales_1000_records!$E:I,ecommerce_sales_1000_records!$G:K,G$9,ecommerce_sales_1000_records!$C:G,MTD!$A13) -> 727.74 | H13: =SUMIFS(ecommerce_sales_1000_records!$E:J,ecommerce_sales_1000_records!$G:L,H$9,ecommerce_sales_1000_records!$C:H,MTD!$A13) -> 4514.24 | I13: =SUMIFS(ecommerce_sales_1000_records!$E:K,ecommerce_sales_1000_records!$G:M,I$9,ecommerce_sales_1000_records!$C:I,MTD!$A13) -> 1908.16 | J13: =SUMIFS(ecommerce_sales_1000_records!$E:L,ecommerce_sales_1000_records!$G:N,J$9,ecommerce_sales_1000_records!$C:J,MTD!$A13) -> 0 | K13: =SUMIFS(ecommerce_sales_1000_records!$E:M,ecommerce_sales_1000_records!$G:O,K$9,ecommerce_sales_1000_records!$C:K,MTD!$A13) -> 2345.06 | L13: =SUMIFS(ecommerce_sales_1000_records!$E:N,ecommerce_sales_1000_records!$G:P,L$9,ecommerce_sales_1000_records!$C:L,MTD!$A13) -> 1843.7 | M13: =SUMIFS(ecommerce_sales_1000_records!$E:O,ecommerce_sales_1000_records!$G:Q,M$9,ecommerce_sales_1000_records!$C:M,MTD!$A13) -> 4567.69 | N13: =SUMIFS(ecommerce_sales_1000_records!$E:P,ecommerce_sales_1000_records!$G:R,N$9,ecommerce_sales_1000_records!$C:N,MTD!$A13) -> 4561.91 | O13: =SUMIFS(ecommerce_sales_1000_records!$E:Q,ecommerce_sales_1000_records!$G:S,O$9,ecommerce_sales_1000_records!$C:O,MTD!$A13) -> 0 | P13: =SUMIFS(ecommerce_sales_1000_records!$E:R,ecommerce_sales_1000_records!$G:T,P$9,ecommerce_sales_1000_records!$C:P,MTD!$A13) -> 2492.49 | Q13: =SUMIFS(ecommerce_sales_1000_records!$E:S,ecommerce_sales_1000_records!$G:U,Q$9,ecommerce_sales_1000_records!$C:Q,MTD!$A13) -> 3299.37 | R13: =SUMIFS(ecommerce_sales_1000_records!$E:T,ecommerce_sales_1000_records!$G:V,R$9,ecommerce_sales_1000_records!$C:R,MTD!$A13) -> 0 | S13: =SUMIFS(ecommerce_sales_1000_records!$E:U,ecommerce_sales_1000_records!$G:W,S$9,ecommerce_sales_1000_records!$C:S,MTD!$A13) -> 1683.95 | T13: =SUMIFS(ecommerce_sales_1000_records!$E:V,ecommerce_sales_1000_records!$G:X,T$9,ecommerce_sales_1000_records!$C:T,MTD!$A13) -> 1617.62 | U13: =SUMIFS(ecommerce_sales_1000_records!$E:W,ecommerce_sales_1000_records!$G:Y,U$9,ecommerce_sales_1000_records!$C:U,MTD!$A13) -> 0 | V13: =SUMIFS(ecommerce_sales_1000_records!$E:X,ecommerce_sales_1000_records!$G:Z,V$9,ecommerce_sales_1000_records!$C:V,MTD!$A13) -> 0 | W13: =SUMIFS(ecommerce_sales_1000_records!$E:Y,ecommerce_sales_1000_records!$G:AA,W$9,ecommerce_sales_1000_records!$C:W,MTD!$A13) -> 0 | X13: =SUMIFS(ecommerce_sales_1000_records!$E:Z,ecommerce_sales_1000_records!$G:AB,X$9,ecommerce_sales_1000_records!$C:X,MTD!$A13) -> 2801.9 | Y13: =SUMIFS(ecommerce_sales_1000_records!$E:AA,ecommerce_sales_1000_records!$G:AC,Y$9,ecommerce_sales_1000_records!$C:Y,MTD!$A13) -> 0 | Z13: =SUMIFS(ecommerce_sales_1000_records!$E:AB,ecommerce_sales_1000_records!$G:AD,Z$9,ecommerce_sales_1000_records!$C:Z,MTD!$A13) -> 3269.01 | AA13: =SUMIFS(ecommerce_sales_1000_records!$E:AC,ecommerce_sales_1000_records!$G:AE,AA$9,ecommerce_sales_1000_records!$C:AA,MTD!$A13) -> 0 | AB13: =SUMIFS(ecommerce_sales_1000_records!$E:AD,ecommerce_sales_1000_records!$G:AF,AB$9,ecommerce_sales_1000_records!$C:AB,MTD!$A13) -> 3889.46 | AC13: =SUMIFS(ecommerce_sales_1000_records!$E:AE,ecommerce_sales_1000_records!$G:AG,AC$9,ecommerce_sales_1000_records!$C:AC,MTD!$A13) -> 2300.32 | AD13: =SUMIFS(ecommerce_sales_1000_records!$E:AF,ecommerce_sales_1000_records!$G:AH,AD$9,ecommerce_sales_1000_records!$C:AD,MTD!$A13) -> 1708.4
A14: Home Appliances | B14: =SUM(C14:AG14) -> 126137.84 | C14: =SUMIFS(ecommerce_sales_1000_records!$E:E,ecommerce_sales_1000_records!$G:G,C$9,ecommerce_sales_1000_records!$C:C,MTD!$A14) -> 0 | D14: =SUMIFS(ecommerce_sales_1000_records!$E:F,ecommerce_sales_1000_records!$G:H,D$9,ecommerce_sales_1000_records!$C:D,MTD!$A14) -> 8347.31 | E14: =SUMIFS(ecommerce_sales_1000_records!$E:G,ecommerce_sales_1000_records!$G:I,E$9,ecommerce_sales_1000_records!$C:E,MTD!$A14) -> 3682.94 | F14: =SUMIFS(ecommerce_sales_1000_records!$E:H,ecommerce_sales_1000_records!$G:J,F$9,ecommerce_sales_1000_records!$C:F,MTD!$A14) -> 6338.34 | G14: =SUMIFS(ecommerce_sales_1000_records!$E:I,ecommerce_sales_1000_records!$G:K,G$9,ecommerce_sales_1000_records!$C:G,MTD!$A14) -> 3905.11 | H14: =SUMIFS(ecommerce_sales_1000_records!$E:J,ecommerce_sales_1000_records!$G:L,H$9,ecommerce_sales_1000_records!$C:H,MTD!$A14) -> 3270.54 | I14: =SUMIFS(ecommerce_sales_1000_records!$E:K,ecommerce_sales_1000_records!$G:M,I$9,ecommerce_sales_1000_records!$C:I,MTD!$A14) -> 0 | J14: =SUMIFS(ecommerce_sales_1000_records!$E:L,ecommerce_sales_1000_records!$G:N,J$9,ecommerce_sales_1000_records!$C:J,MTD!$A14) -> 3553.91 | K14: =SUMIFS(ecommerce_sales_1000_records!$E:M,ecommerce_sales_1000_records!$G:O,K$9,ecommerce_sales_1000_records!$C:K,MTD!$A14) -> 3679.05 | L14: =SUMIFS(ecommerce_sales_1000_records!$E:N,ecommerce_sales_1000_records!$G:P,L$9,ecommerce_sales_1000_records!$C:L,MTD!$A14) -> 0 | M14: =SUMIFS(ecommerce_sales_1000_records!$E:O,ecommerce_sales_1000_records!$G:Q,M$9,ecommerce_sales_1000_records!$C:M,MTD!$A14) -> 0 | N14: =SUMIFS(ecommerce_sales_1000_records!$E:P,ecommerce_sales_1000_records!$G:R,N$9,ecommerce_sales_1000_records!$C:N,MTD!$A14) -> 8196.33 | O14: =SUMIFS(ecommerce_sales_1000_records!$E:Q,ecommerce_sales_1000_records!$G:S,O$9,ecommerce_sales_1000_records!$C:O,MTD!$A14) -> 0 | P14: =SUMIFS(ecommerce_sales_1000_records!$E:R,ecommerce_sales_1000_records!$G:T,P$9,ecommerce_sales_1000_records!$C:P,MTD!$A14) -> 0 | Q14: =SUMIFS(ecommerce_sales_1000_records!$E:S,ecommerce_sales_1000_records!$G:U,Q$9,ecommerce_sales_1000_records!$C:Q,MTD!$A14) -> 6311.25 | R14: =SUMIFS(ecommerce_sales_1000_records!$E:T,ecommerce_sales_1000_records!$G:V,R$9,ecommerce_sales_1000_records!$C:R,MTD!$A14) -> 0 | S14: =SUMIFS(ecommerce_sales_1000_records!$E:U,ecommerce_sales_1000_records!$G:W,S$9,ecommerce_sales_1000_records!$C:S,MTD!$A14) -> 3852.86 | T14: =SUMIFS(ecommerce_sales_1000_records!$E:V,ecommerce_sales_1000_records!$G:X,T$9,ecommerce_sales_1000_records!$C:T,MTD!$A14) -> 9590.27 | U14: =SUMIFS(ecommerce_sales_1000_records!$E:W,ecommerce_sales_1000_records!$G:Y,U$9,ecommerce_sales_1000_records!$C:U,MTD!$A14) -> 7810.25 | V14: =SUMIFS(ecommerce_sales_1000_records!$E:X,ecommerce_sales_1000_records!$G:Z,V$9,ecommerce_sales_1000_records!$C:V,MTD!$A14) -> 3564.18 | W14: =SUMIFS(ecommerce_sales_1000_records!$E:Y,ecommerce_sales_1000_records!$G:AA,W$9,ecommerce_sales_1000_records!$C:W,MTD!$A14) -> 14483.6 | X14: =SUMIFS(ecommerce_sales_1000_records!$E:Z,ecommerce_sales_1000_records!$G:AB,X$9,ecommerce_sales_1000_records!$C:X,MTD!$A14) -> 0 | Y14: =SUMIFS(ecommerce_sales_1000_records!$E:AA,ecommerce_sales_1000_records!$G:AC,Y$9,ecommerce_sales_1000_records!$C:Y,MTD!$A14) -> 19687.28 | Z14: =SUMIFS(ecommerce_sales_1000_records!$E:AB,ecommerce_sales_1000_records!$G:AD,Z$9,ecommerce_sales_1000_records!$C:Z,MTD!$A14) -> 0 | AA14: =SUMIFS(ecommerce_sales_1000_records!$E:AC,ecommerce_sales_1000_records!$G:AE,AA$9,ecommerce_sales_1000_records!$C:AA,MTD!$A14) -> 0 | AB14: =SUMIFS(ecommerce_sales_1000_records!$E:AD,ecommerce_sales_1000_records!$G:AF,AB$9,ecommerce_sales_1000_records!$C:AB,MTD!$A14) -> 6546.83 | AC14: =SUMIFS(ecommerce_sales_1000_records!$E:AE,ecommerce_sales_1000_records!$G:AG,AC$9,ecommerce_sales_1000_records!$C:AC,MTD!$A14) -> 6304.56 | AD14: =SUMIFS(ecommerce_sales_1000_records!$E:AF,ecommerce_sales_1000_records!$G:AH,AD$9,ecommerce_sales_1000_records!$C:AD,MTD!$A14) -> 7013.23
A15: Total Sales : | B15: =SUM(B10:B14) -> 1332532.8 | C15: =SUM(C10:C14) -> 50767.22 | D15: =SUM(D10:D14) -> 79723.51 | E15: =SUM(E10:E14) -> 98274.41 | F15: =SUM(F10:F14) -> 101596.64 | G15: =SUM(G10:G14) -> 61588.99 | H15: =SUM(H10:H14) -> 88654.21 | I15: =SUM(I10:I14) -> 34365.07 | ... AD15: =SUM(AD10:AD14) -> 58917.92
A17: Date | B17: 46082 | C17: 46082 | D17: =C17+1 -> 46083 | E17: =D17+1 -> 46084 | F17: =E17+1 -> 46085 | G17: =F17+1 -> 46086 | H17: =G17+1 -> 46087 | I17: =H17+1 -> 46088 | J17: =I17+1 -> 46089 | K17: =J17+1 -> 46090 | ... AG17: =AF17+1 -> 46112
